[2024-08-01T15:06:56.947+0000] {local_task_job_runner.py:120} INFO - ::group::Pre task execution logs
[2024-08-01T15:06:57.081+0000] {taskinstance.py:2076} INFO - Dependencies all met for dep_context=non-requeueable deps ti=<TaskInstance: fill_tables_on_rd.Start manual__2024-08-01T15:06:51.553068+00:00 [queued]>
[2024-08-01T15:06:57.101+0000] {taskinstance.py:2076} INFO - Dependencies all met for dep_context=requeueable deps ti=<TaskInstance: fill_tables_on_rd.Start manual__2024-08-01T15:06:51.553068+00:00 [queued]>
[2024-08-01T15:06:57.103+0000] {taskinstance.py:2306} INFO - Starting attempt 1 of 2
[2024-08-01T15:06:57.130+0000] {taskinstance.py:2330} INFO - Executing <Task(PythonOperator): Start> on 2024-08-01 15:06:51.553068+00:00
[2024-08-01T15:06:57.141+0000] {standard_task_runner.py:90} INFO - Running: ['***', 'tasks', 'run', 'fill_tables_on_rd', 'Start', 'manual__2024-08-01T15:06:51.553068+00:00', '--job-id', '733', '--raw', '--subdir', 'DAGS_FOLDER/fill_tables.py', '--cfg-path', '/tmp/tmprgua4xip']
[2024-08-01T15:06:57.145+0000] {standard_task_runner.py:91} INFO - Job 733: Subtask Start
[2024-08-01T15:06:57.145+0000] {logging_mixin.py:188} WARNING - /home/***/.local/lib/python3.12/site-packages/***/task/task_runner/standard_task_runner.py:61 DeprecationWarning: This process (pid=1379) is multi-threaded, use of fork() may lead to deadlocks in the child.
[2024-08-01T15:06:57.147+0000] {standard_task_runner.py:63} INFO - Started process 1380 to run task
[2024-08-01T15:06:57.198+0000] {task_command.py:426} INFO - Running <TaskInstance: fill_tables_on_rd.Start manual__2024-08-01T15:06:51.553068+00:00 [running]> on host 2634975b7554
[2024-08-01T15:06:57.533+0000] {taskinstance.py:2648} INFO - Exporting env vars: AIRFLOW_CTX_DAG_OWNER='***' AIRFLOW_CTX_DAG_ID='fill_tables_on_rd' AIRFLOW_CTX_TASK_ID='Start' AIRFLOW_CTX_EXECUTION_DATE='2024-08-01T15:06:51.553068+00:00' AIRFLOW_CTX_TRY_NUMBER='1' AIRFLOW_CTX_DAG_RUN_ID='manual__2024-08-01T15:06:51.553068+00:00'
[2024-08-01T15:06:57.535+0000] {taskinstance.py:430} INFO - ::endgroup::
[2024-08-01T15:06:57.645+0000] {base.py:84} INFO - Using connection ID 'postgres_default2' for task execution.
[2024-08-01T15:06:57.665+0000] {taskinstance.py:441} INFO - ::group::Post task execution logs
[2024-08-01T15:06:57.668+0000] {taskinstance.py:2905} ERROR - Task failed with exception
Traceback (most recent call last):
  File "/home/airflow/.local/lib/python3.12/site-packages/airflow/models/taskinstance.py", line 465, in _execute_task
    result = _execute_callable(context=context, **execute_callable_kwargs)
             ^^^^^^^^^^^^^^^^^^^^^^^^^^^^^^^^^^^^^^^^^^^^^^^^^^^^^^^^^^^^^
  File "/home/airflow/.local/lib/python3.12/site-packages/airflow/models/taskinstance.py", line 432, in _execute_callable
    return execute_callable(context=context, **execute_callable_kwargs)
           ^^^^^^^^^^^^^^^^^^^^^^^^^^^^^^^^^^^^^^^^^^^^^^^^^^^^^^^^^^^^
  File "/home/airflow/.local/lib/python3.12/site-packages/airflow/models/baseoperator.py", line 401, in wrapper
    return func(self, *args, **kwargs)
           ^^^^^^^^^^^^^^^^^^^^^^^^^^^
  File "/home/airflow/.local/lib/python3.12/site-packages/airflow/operators/python.py", line 235, in execute
    return_value = self.execute_callable()
                   ^^^^^^^^^^^^^^^^^^^^^^^
  File "/home/airflow/.local/lib/python3.12/site-packages/airflow/operators/python.py", line 252, in execute_callable
    return self.python_callable(*self.op_args, **self.op_kwargs)
           ^^^^^^^^^^^^^^^^^^^^^^^^^^^^^^^^^^^^^^^^^^^^^^^^^^^^^
  File "/opt/airflow/dags/fill_tables.py", line 73, in start_process
    cursor.execute(sql, (start_time, 'Start_fill_tables'))
psycopg2.errors.UndefinedTable: relation "logs.logs" does not exist
LINE 2:     INSERT INTO logs.logs (start_time, status)
                        ^

[2024-08-01T15:06:57.715+0000] {taskinstance.py:1206} INFO - Marking task as UP_FOR_RETRY. dag_id=fill_tables_on_rd, task_id=Start, run_id=manual__2024-08-01T15:06:51.553068+00:00, execution_date=20240801T150651, start_date=20240801T150657, end_date=20240801T150657
[2024-08-01T15:06:57.746+0000] {standard_task_runner.py:110} ERROR - Failed to execute job 733 for task Start (relation "logs.logs" does not exist
LINE 2:     INSERT INTO logs.logs (start_time, status)
                        ^
; 1380)
[2024-08-01T15:06:57.768+0000] {local_task_job_runner.py:240} INFO - Task exited with return code 1
[2024-08-01T15:06:57.800+0000] {taskinstance.py:3503} INFO - 0 downstream tasks scheduled from follow-on schedule check
[2024-08-01T15:06:57.803+0000] {local_task_job_runner.py:222} INFO - ::endgroup::
